[2025-10-17T19:41:34.994+0000] {local_task_job_runner.py:123} INFO - ::group::Pre task execution logs
[2025-10-17T19:41:35.003+0000] {taskinstance.py:2613} INFO - Dependencies all met for dep_context=non-requeueable deps ti=<TaskInstance: docker_tasks_pipeline.ingest manual__2025-10-17T19:41:34.015790+00:00 [queued]>
[2025-10-17T19:41:35.005+0000] {taskinstance.py:2613} INFO - Dependencies all met for dep_context=requeueable deps ti=<TaskInstance: docker_tasks_pipeline.ingest manual__2025-10-17T19:41:34.015790+00:00 [queued]>
[2025-10-17T19:41:35.005+0000] {taskinstance.py:2866} INFO - Starting attempt 1 of 2
[2025-10-17T19:41:35.009+0000] {taskinstance.py:2889} INFO - Executing <Task(DockerOperator): ingest> on 2025-10-17 19:41:34.015790+00:00
[2025-10-17T19:41:35.011+0000] {standard_task_runner.py:72} INFO - Started process 437 to run task
[2025-10-17T19:41:35.012+0000] {standard_task_runner.py:104} INFO - Running: ['***', 'tasks', 'run', 'docker_tasks_pipeline', 'ingest', 'manual__2025-10-17T19:41:34.015790+00:00', '--job-id', '9', '--raw', '--subdir', 'DAGS_FOLDER/docker_tasks_pipeline.py', '--cfg-path', '/tmp/tmpusbkd1ed']
[2025-10-17T19:41:35.013+0000] {standard_task_runner.py:105} INFO - Job 9: Subtask ingest
[2025-10-17T19:41:35.033+0000] {task_command.py:467} INFO - Running <TaskInstance: docker_tasks_pipeline.ingest manual__2025-10-17T19:41:34.015790+00:00 [running]> on host 161f5a2f5c62
[2025-10-17T19:41:35.065+0000] {taskinstance.py:3132} INFO - Exporting env vars: AIRFLOW_CTX_DAG_OWNER='***' AIRFLOW_CTX_DAG_ID='docker_tasks_pipeline' AIRFLOW_CTX_TASK_ID='ingest' AIRFLOW_CTX_EXECUTION_DATE='2025-10-17T19:41:34.015790+00:00' AIRFLOW_CTX_TRY_NUMBER='1' AIRFLOW_CTX_DAG_RUN_ID='manual__2025-10-17T19:41:34.015790+00:00'
[2025-10-17T19:41:35.065+0000] {taskinstance.py:731} INFO - ::endgroup::
[2025-10-17T19:41:35.079+0000] {docker.py:478} INFO - ::group::Pulling docker image etl-tasks:3.1
[2025-10-17T19:41:36.764+0000] {taskinstance.py:3311} ERROR - Task failed with exception
Traceback (most recent call last):
  File "/home/airflow/.local/lib/python3.11/site-packages/docker/api/client.py", line 275, in _raise_for_status
    response.raise_for_status()
  File "/home/airflow/.local/lib/python3.11/site-packages/requests/models.py", line 1024, in raise_for_status
    raise HTTPError(http_error_msg, response=self)
requests.exceptions.HTTPError: 404 Client Error: Not Found for url: http+docker://localhost/v1.51/images/create?tag=3.1&fromImage=etl-tasks

The above exception was the direct cause of the following exception:

Traceback (most recent call last):
  File "/home/airflow/.local/lib/python3.11/site-packages/airflow/models/taskinstance.py", line 767, in _execute_task
    result = _execute_callable(context=context, **execute_callable_kwargs)
             ^^^^^^^^^^^^^^^^^^^^^^^^^^^^^^^^^^^^^^^^^^^^^^^^^^^^^^^^^^^^^
  File "/home/airflow/.local/lib/python3.11/site-packages/airflow/models/taskinstance.py", line 733, in _execute_callable
    return ExecutionCallableRunner(
           ^^^^^^^^^^^^^^^^^^^^^^^^
  File "/home/airflow/.local/lib/python3.11/site-packages/airflow/utils/operator_helpers.py", line 252, in run
    return self.func(*args, **kwargs)
           ^^^^^^^^^^^^^^^^^^^^^^^^^^
  File "/home/airflow/.local/lib/python3.11/site-packages/airflow/models/baseoperator.py", line 417, in wrapper
    return func(self, *args, **kwargs)
           ^^^^^^^^^^^^^^^^^^^^^^^^^^^
  File "/home/airflow/.local/lib/python3.11/site-packages/airflow/providers/docker/operators/docker.py", line 480, in execute
    for output in self.cli.pull(self.image, stream=True, decode=True):
                  ^^^^^^^^^^^^^^^^^^^^^^^^^^^^^^^^^^^^^^^^^^^^^^^^^^^
  File "/home/airflow/.local/lib/python3.11/site-packages/docker/api/image.py", line 429, in pull
    self._raise_for_status(response)
  File "/home/airflow/.local/lib/python3.11/site-packages/docker/api/client.py", line 277, in _raise_for_status
    raise create_api_error_from_http_exception(e) from e
          ^^^^^^^^^^^^^^^^^^^^^^^^^^^^^^^^^^^^^^^
  File "/home/airflow/.local/lib/python3.11/site-packages/docker/errors.py", line 39, in create_api_error_from_http_exception
    raise cls(e, response=response, explanation=explanation) from e
docker.errors.ImageNotFound: 404 Client Error for http+docker://localhost/v1.51/images/create?tag=3.1&fromImage=etl-tasks: Not Found ("pull access denied for etl-tasks, repository does not exist or may require 'docker login'")
[2025-10-17T19:41:36.781+0000] {taskinstance.py:1225} INFO - Marking task as UP_FOR_RETRY. dag_id=docker_tasks_pipeline, task_id=ingest, run_id=manual__2025-10-17T19:41:34.015790+00:00, execution_date=20251017T194134, start_date=20251017T194135, end_date=20251017T194136
[2025-10-17T19:41:36.789+0000] {taskinstance.py:340} INFO - ::group::Post task execution logs
[2025-10-17T19:41:36.790+0000] {standard_task_runner.py:124} ERROR - Failed to execute job 9 for task ingest (404 Client Error for http+docker://localhost/v1.51/images/create?tag=3.1&fromImage=etl-tasks: Not Found ("pull access denied for etl-tasks, repository does not exist or may require 'docker login'"); 437)
Traceback (most recent call last):
  File "/home/airflow/.local/lib/python3.11/site-packages/docker/api/client.py", line 275, in _raise_for_status
    response.raise_for_status()
  File "/home/airflow/.local/lib/python3.11/site-packages/requests/models.py", line 1024, in raise_for_status
    raise HTTPError(http_error_msg, response=self)
requests.exceptions.HTTPError: 404 Client Error: Not Found for url: http+docker://localhost/v1.51/images/create?tag=3.1&fromImage=etl-tasks

The above exception was the direct cause of the following exception:

Traceback (most recent call last):
  File "/home/airflow/.local/lib/python3.11/site-packages/airflow/task/task_runner/standard_task_runner.py", line 117, in _start_by_fork
    ret = args.func(args, dag=self.dag)
          ^^^^^^^^^^^^^^^^^^^^^^^^^^^^^
  File "/home/airflow/.local/lib/python3.11/site-packages/airflow/cli/cli_config.py", line 49, in command
    return func(*args, **kwargs)
           ^^^^^^^^^^^^^^^^^^^^^
  File "/home/airflow/.local/lib/python3.11/site-packages/airflow/utils/cli.py", line 116, in wrapper
    return f(*args, **kwargs)
           ^^^^^^^^^^^^^^^^^^
  File "/home/airflow/.local/lib/python3.11/site-packages/airflow/cli/commands/task_command.py", line 483, in task_run
    task_return_code = _run_task_by_selected_method(args, _dag, ti)
                       ^^^^^^^^^^^^^^^^^^^^^^^^^^^^^^^^^^^^^^^^^^^^
  File "/home/airflow/.local/lib/python3.11/site-packages/airflow/cli/commands/task_command.py", line 256, in _run_task_by_selected_method
    return _run_raw_task(args, ti)
           ^^^^^^^^^^^^^^^^^^^^^^^
  File "/home/airflow/.local/lib/python3.11/site-packages/airflow/cli/commands/task_command.py", line 341, in _run_raw_task
    return ti._run_raw_task(
           ^^^^^^^^^^^^^^^^^
  File "/home/airflow/.local/lib/python3.11/site-packages/airflow/utils/session.py", line 97, in wrapper
    return func(*args, session=session, **kwargs)
           ^^^^^^^^^^^^^^^^^^^^^^^^^^^^^^^^^^^^^^
  File "/home/airflow/.local/lib/python3.11/site-packages/airflow/models/taskinstance.py", line 3005, in _run_raw_task
    return _run_raw_task(
           ^^^^^^^^^^^^^^
  File "/home/airflow/.local/lib/python3.11/site-packages/airflow/models/taskinstance.py", line 273, in _run_raw_task
    TaskInstance._execute_task_with_callbacks(
  File "/home/airflow/.local/lib/python3.11/site-packages/airflow/models/taskinstance.py", line 3159, in _execute_task_with_callbacks
    result = self._execute_task(context, task_orig)
             ^^^^^^^^^^^^^^^^^^^^^^^^^^^^^^^^^^^^^^
  File "/home/airflow/.local/lib/python3.11/site-packages/airflow/models/taskinstance.py", line 3183, in _execute_task
    return _execute_task(self, context, task_orig)
           ^^^^^^^^^^^^^^^^^^^^^^^^^^^^^^^^^^^^^^^
  File "/home/airflow/.local/lib/python3.11/site-packages/airflow/models/taskinstance.py", line 767, in _execute_task
    result = _execute_callable(context=context, **execute_callable_kwargs)
             ^^^^^^^^^^^^^^^^^^^^^^^^^^^^^^^^^^^^^^^^^^^^^^^^^^^^^^^^^^^^^
  File "/home/airflow/.local/lib/python3.11/site-packages/airflow/models/taskinstance.py", line 733, in _execute_callable
    return ExecutionCallableRunner(
           ^^^^^^^^^^^^^^^^^^^^^^^^
  File "/home/airflow/.local/lib/python3.11/site-packages/airflow/utils/operator_helpers.py", line 252, in run
    return self.func(*args, **kwargs)
           ^^^^^^^^^^^^^^^^^^^^^^^^^^
  File "/home/airflow/.local/lib/python3.11/site-packages/airflow/models/baseoperator.py", line 417, in wrapper
    return func(self, *args, **kwargs)
           ^^^^^^^^^^^^^^^^^^^^^^^^^^^
  File "/home/airflow/.local/lib/python3.11/site-packages/airflow/providers/docker/operators/docker.py", line 480, in execute
    for output in self.cli.pull(self.image, stream=True, decode=True):
                  ^^^^^^^^^^^^^^^^^^^^^^^^^^^^^^^^^^^^^^^^^^^^^^^^^^^
  File "/home/airflow/.local/lib/python3.11/site-packages/docker/api/image.py", line 429, in pull
    self._raise_for_status(response)
  File "/home/airflow/.local/lib/python3.11/site-packages/docker/api/client.py", line 277, in _raise_for_status
    raise create_api_error_from_http_exception(e) from e
          ^^^^^^^^^^^^^^^^^^^^^^^^^^^^^^^^^^^^^^^
  File "/home/airflow/.local/lib/python3.11/site-packages/docker/errors.py", line 39, in create_api_error_from_http_exception
    raise cls(e, response=response, explanation=explanation) from e
docker.errors.ImageNotFound: 404 Client Error for http+docker://localhost/v1.51/images/create?tag=3.1&fromImage=etl-tasks: Not Found ("pull access denied for etl-tasks, repository does not exist or may require 'docker login'")
[2025-10-17T19:41:36.814+0000] {local_task_job_runner.py:266} INFO - Task exited with return code 1
[2025-10-17T19:41:36.823+0000] {local_task_job_runner.py:245} INFO - ::endgroup::
